[2024-07-25T16:19:05.127+0000] {taskinstance.py:1956} INFO - Dependencies all met for dep_context=non-requeueable deps ti=<TaskInstance: crypto_pipeline.load_data scheduled__2024-07-25T16:10:00+00:00 [queued]>
[2024-07-25T16:19:05.144+0000] {taskinstance.py:1956} INFO - Dependencies all met for dep_context=requeueable deps ti=<TaskInstance: crypto_pipeline.load_data scheduled__2024-07-25T16:10:00+00:00 [queued]>
[2024-07-25T16:19:05.146+0000] {taskinstance.py:2170} INFO - Starting attempt 1 of 1
[2024-07-25T16:19:05.170+0000] {taskinstance.py:2191} INFO - Executing <Task(PythonOperator): load_data> on 2024-07-25 16:10:00+00:00
[2024-07-25T16:19:05.185+0000] {standard_task_runner.py:60} INFO - Started process 24027 to run task
[2024-07-25T16:19:05.188+0000] {standard_task_runner.py:87} INFO - Running: ['***', 'tasks', 'run', 'crypto_pipeline', 'load_data', 'scheduled__2024-07-25T16:10:00+00:00', '--job-id', '1236', '--raw', '--subdir', 'DAGS_FOLDER/crypto_pipeline_dag.py', '--cfg-path', '/tmp/tmpqybuosyj']
[2024-07-25T16:19:05.190+0000] {standard_task_runner.py:88} INFO - Job 1236: Subtask load_data
[2024-07-25T16:19:05.251+0000] {task_command.py:423} INFO - Running <TaskInstance: crypto_pipeline.load_data scheduled__2024-07-25T16:10:00+00:00 [running]> on host 58dd90220664
[2024-07-25T16:19:05.365+0000] {taskinstance.py:2480} INFO - Exporting env vars: AIRFLOW_CTX_DAG_OWNER='***' AIRFLOW_CTX_DAG_ID='crypto_pipeline' AIRFLOW_CTX_TASK_ID='load_data' AIRFLOW_CTX_EXECUTION_DATE='2024-07-25T16:10:00+00:00' AIRFLOW_CTX_TRY_NUMBER='1' AIRFLOW_CTX_DAG_RUN_ID='scheduled__2024-07-25T16:10:00+00:00'
[2024-07-25T16:19:23.893+0000] {taskinstance.py:2698} ERROR - Task failed with exception
Traceback (most recent call last):
  File "/home/airflow/.local/lib/python3.8/site-packages/airflow/models/taskinstance.py", line 433, in _execute_task
    result = execute_callable(context=context, **execute_callable_kwargs)
  File "/home/airflow/.local/lib/python3.8/site-packages/airflow/operators/python.py", line 199, in execute
    return_value = self.execute_callable()
  File "/home/airflow/.local/lib/python3.8/site-packages/airflow/operators/python.py", line 216, in execute_callable
    return self.python_callable(*self.op_args, **self.op_kwargs)
  File "/opt/airflow/dags/crypto_pipeline_dag.py", line 43, in load_data_with_xcom
    load_data(
  File "/opt/airflow/Program.py", line 70, in load_data
    fetch_and_load(host, port, database, user, password,
  File "/opt/airflow/src/fetch_and_load.py", line 22, in fetch_and_load
    conn = psycopg2.connect (
  File "/home/airflow/.local/lib/python3.8/site-packages/psycopg2/__init__.py", line 122, in connect
    conn = _connect(dsn, connection_factory=connection_factory, **kwasync)
psycopg2.OperationalError: connection to server at "34.162.73.30", port 5432 failed: SSL SYSCALL error: EOF detected

[2024-07-25T16:19:24.061+0000] {taskinstance.py:1138} INFO - Marking task as FAILED. dag_id=crypto_pipeline, task_id=load_data, execution_date=20240725T161000, start_date=20240725T161905, end_date=20240725T161924
[2024-07-25T16:19:24.078+0000] {standard_task_runner.py:107} ERROR - Failed to execute job 1236 for task load_data (connection to server at "34.162.73.30", port 5432 failed: SSL SYSCALL error: EOF detected
; 24027)
[2024-07-25T16:19:24.120+0000] {local_task_job_runner.py:234} INFO - Task exited with return code 1
[2024-07-25T16:19:24.138+0000] {taskinstance.py:3280} INFO - 0 downstream tasks scheduled from follow-on schedule check
