[2024-07-19T18:08:27.980+0000] {taskinstance.py:1956} INFO - Dependencies all met for dep_context=non-requeueable deps ti=<TaskInstance: crypto_pipeline.process_data manual__2024-07-19T18:08:22.950524+00:00 [queued]>
[2024-07-19T18:08:27.986+0000] {taskinstance.py:1956} INFO - Dependencies all met for dep_context=requeueable deps ti=<TaskInstance: crypto_pipeline.process_data manual__2024-07-19T18:08:22.950524+00:00 [queued]>
[2024-07-19T18:08:27.987+0000] {taskinstance.py:2170} INFO - Starting attempt 1 of 1
[2024-07-19T18:08:27.997+0000] {taskinstance.py:2191} INFO - Executing <Task(PythonOperator): process_data> on 2024-07-19 18:08:22.950524+00:00
[2024-07-19T18:08:28.002+0000] {standard_task_runner.py:60} INFO - Started process 122 to run task
[2024-07-19T18:08:28.005+0000] {standard_task_runner.py:87} INFO - Running: ['***', 'tasks', 'run', 'crypto_pipeline', 'process_data', 'manual__2024-07-19T18:08:22.950524+00:00', '--job-id', '299', '--raw', '--subdir', 'DAGS_FOLDER/crypto_pipeline_dag.py', '--cfg-path', '/tmp/tmppih47xvx']
[2024-07-19T18:08:28.006+0000] {standard_task_runner.py:88} INFO - Job 299: Subtask process_data
[2024-07-19T18:08:28.043+0000] {task_command.py:423} INFO - Running <TaskInstance: crypto_pipeline.process_data manual__2024-07-19T18:08:22.950524+00:00 [running]> on host 58dd90220664
[2024-07-19T18:08:28.098+0000] {taskinstance.py:2480} INFO - Exporting env vars: AIRFLOW_CTX_DAG_OWNER='***' AIRFLOW_CTX_DAG_ID='crypto_pipeline' AIRFLOW_CTX_TASK_ID='process_data' AIRFLOW_CTX_EXECUTION_DATE='2024-07-19T18:08:22.950524+00:00' AIRFLOW_CTX_TRY_NUMBER='1' AIRFLOW_CTX_DAG_RUN_ID='manual__2024-07-19T18:08:22.950524+00:00'
[2024-07-19T18:08:28.099+0000] {taskinstance.py:2698} ERROR - Task failed with exception
Traceback (most recent call last):
  File "/home/airflow/.local/lib/python3.8/site-packages/airflow/models/taskinstance.py", line 433, in _execute_task
    result = execute_callable(context=context, **execute_callable_kwargs)
  File "/home/airflow/.local/lib/python3.8/site-packages/airflow/operators/python.py", line 199, in execute
    return_value = self.execute_callable()
  File "/home/airflow/.local/lib/python3.8/site-packages/airflow/operators/python.py", line 216, in execute_callable
    return self.python_callable(*self.op_args, **self.op_kwargs)
  File "/opt/airflow/dags/crypto_pipeline_dag.py", line 63, in <lambda>
    python_callable=lambda: process_data(fetch_data_task.output),
  File "/opt/airflow/Program.py", line 62, in process_data
    datetime_col = pd.to_datetime(dataframe['datetime'].iloc[0])
AttributeError: 'PlainXComArg' object has no attribute 'iloc'
[2024-07-19T18:08:28.110+0000] {taskinstance.py:1138} INFO - Marking task as FAILED. dag_id=crypto_pipeline, task_id=process_data, execution_date=20240719T180822, start_date=20240719T180827, end_date=20240719T180828
[2024-07-19T18:08:28.119+0000] {standard_task_runner.py:107} ERROR - Failed to execute job 299 for task process_data ('PlainXComArg' object has no attribute 'iloc'; 122)
[2024-07-19T18:08:28.138+0000] {local_task_job_runner.py:234} INFO - Task exited with return code 1
[2024-07-19T18:08:28.157+0000] {taskinstance.py:3280} INFO - 0 downstream tasks scheduled from follow-on schedule check
