[2024-08-01T19:22:44.524+0000] {scheduler_job_runner.py:1586} WARNING - Marking task instance <TaskInstance: crypto_pipeline.fetch_data scheduled__2024-08-01T19:05:00+00:00 [queued]> stuck in queued as failed. If the task instance has available retries, it will be retried.
[2024-08-01T19:22:44.894+0000] {scheduler_job_runner.py:781} ERROR - Executor reports task instance <TaskInstance: crypto_pipeline.fetch_data scheduled__2024-08-01T19:05:00+00:00 [queued]> finished (failed) although the task says it's queued. (Info: None) Was the task killed externally?
