[2024-07-20T22:54:03.650+0000] {taskinstance.py:1956} INFO - Dependencies all met for dep_context=non-requeueable deps ti=<TaskInstance: crypto_pipeline.fetch_data scheduled__2024-07-20T22:25:00+00:00 [queued]>
[2024-07-20T22:54:03.668+0000] {taskinstance.py:1956} INFO - Dependencies all met for dep_context=requeueable deps ti=<TaskInstance: crypto_pipeline.fetch_data scheduled__2024-07-20T22:25:00+00:00 [queued]>
[2024-07-20T22:54:03.669+0000] {taskinstance.py:2170} INFO - Starting attempt 1 of 1
[2024-07-20T22:54:03.692+0000] {taskinstance.py:2191} INFO - Executing <Task(PythonOperator): fetch_data> on 2024-07-20 22:25:00+00:00
[2024-07-20T22:54:03.709+0000] {standard_task_runner.py:60} INFO - Started process 5975 to run task
[2024-07-20T22:54:03.714+0000] {standard_task_runner.py:87} INFO - Running: ['***', 'tasks', 'run', 'crypto_pipeline', 'fetch_data', 'scheduled__2024-07-20T22:25:00+00:00', '--job-id', '533', '--raw', '--subdir', 'DAGS_FOLDER/crypto_pipeline_dag.py', '--cfg-path', '/tmp/tmpsau6z19l']
[2024-07-20T22:54:03.718+0000] {standard_task_runner.py:88} INFO - Job 533: Subtask fetch_data
[2024-07-20T22:54:03.791+0000] {task_command.py:423} INFO - Running <TaskInstance: crypto_pipeline.fetch_data scheduled__2024-07-20T22:25:00+00:00 [running]> on host 58dd90220664
[2024-07-20T22:54:04.201+0000] {taskinstance.py:2480} INFO - Exporting env vars: AIRFLOW_CTX_DAG_OWNER='***' AIRFLOW_CTX_DAG_ID='crypto_pipeline' AIRFLOW_CTX_TASK_ID='fetch_data' AIRFLOW_CTX_EXECUTION_DATE='2024-07-20T22:25:00+00:00' AIRFLOW_CTX_TRY_NUMBER='1' AIRFLOW_CTX_DAG_RUN_ID='scheduled__2024-07-20T22:25:00+00:00'
[2024-07-21T23:56:00.059+0000] {taskinstance.py:2698} ERROR - Task failed with exception
Traceback (most recent call last):
  File "/home/airflow/.local/lib/python3.8/site-packages/urllib3/connection.py", line 174, in _new_conn
    conn = connection.create_connection(
  File "/home/airflow/.local/lib/python3.8/site-packages/urllib3/util/connection.py", line 95, in create_connection
    raise err
  File "/home/airflow/.local/lib/python3.8/site-packages/urllib3/util/connection.py", line 85, in create_connection
    sock.connect(sa)
ConnectionRefusedError: [Errno 111] Connection refused

During handling of the above exception, another exception occurred:

Traceback (most recent call last):
  File "/home/airflow/.local/lib/python3.8/site-packages/urllib3/connectionpool.py", line 715, in urlopen
    httplib_response = self._make_request(
  File "/home/airflow/.local/lib/python3.8/site-packages/urllib3/connectionpool.py", line 404, in _make_request
    self._validate_conn(conn)
  File "/home/airflow/.local/lib/python3.8/site-packages/urllib3/connectionpool.py", line 1058, in _validate_conn
    conn.connect()
  File "/home/airflow/.local/lib/python3.8/site-packages/urllib3/connection.py", line 363, in connect
    self.sock = conn = self._new_conn()
  File "/home/airflow/.local/lib/python3.8/site-packages/urllib3/connection.py", line 186, in _new_conn
    raise NewConnectionError(
urllib3.exceptions.NewConnectionError: <urllib3.connection.HTTPSConnection object at 0x7f2913066280>: Failed to establish a new connection: [Errno 111] Connection refused

During handling of the above exception, another exception occurred:

Traceback (most recent call last):
  File "/home/airflow/.local/lib/python3.8/site-packages/requests/adapters.py", line 486, in send
    resp = conn.urlopen(
  File "/home/airflow/.local/lib/python3.8/site-packages/urllib3/connectionpool.py", line 799, in urlopen
    retries = retries.increment(
  File "/home/airflow/.local/lib/python3.8/site-packages/urllib3/util/retry.py", line 592, in increment
    raise MaxRetryError(_pool, url, error or ResponseError(cause))
urllib3.exceptions.MaxRetryError: HTTPSConnectionPool(host='api.binance.com', port=443): Max retries exceeded with url: /api/v3/account?timestamp=1721606157559&signature=319427b6bed782f47f1e2f3f3c0d541d10f7b372e8e986b0b7aad0e881d01bce (Caused by NewConnectionError('<urllib3.connection.HTTPSConnection object at 0x7f2913066280>: Failed to establish a new connection: [Errno 111] Connection refused'))

During handling of the above exception, another exception occurred:

Traceback (most recent call last):
  File "/home/airflow/.local/lib/python3.8/site-packages/airflow/models/taskinstance.py", line 433, in _execute_task
    result = execute_callable(context=context, **execute_callable_kwargs)
  File "/home/airflow/.local/lib/python3.8/site-packages/airflow/operators/python.py", line 199, in execute
    return_value = self.execute_callable()
  File "/home/airflow/.local/lib/python3.8/site-packages/airflow/operators/python.py", line 216, in execute_callable
    return self.python_callable(*self.op_args, **self.op_kwargs)
  File "/opt/airflow/dags/crypto_pipeline_dag.py", line 28, in fetch_data_with_xcom
    df = fetch_data()
  File "/opt/airflow/Program.py", line 11, in fetch_data
    return generate_dataframe(api_key, signature_key)
  File "/opt/airflow/src/generate_data_frame.py", line 17, in generate_dataframe
    crypto_amounts = get_crypto_amounts(api_key, signature_key)
  File "/opt/airflow/src/extract_crypto_amounts.py", line 20, in get_crypto_amounts
    response = requests.get(url, headers=headers)
  File "/home/airflow/.local/lib/python3.8/site-packages/requests/api.py", line 73, in get
    return request("get", url, params=params, **kwargs)
  File "/home/airflow/.local/lib/python3.8/site-packages/requests/api.py", line 59, in request
    return session.request(method=method, url=url, **kwargs)
  File "/home/airflow/.local/lib/python3.8/site-packages/requests/sessions.py", line 589, in request
    resp = self.send(prep, **send_kwargs)
  File "/home/airflow/.local/lib/python3.8/site-packages/requests/sessions.py", line 703, in send
    r = adapter.send(request, **kwargs)
  File "/home/airflow/.local/lib/python3.8/site-packages/requests/adapters.py", line 519, in send
    raise ConnectionError(e, request=request)
requests.exceptions.ConnectionError: HTTPSConnectionPool(host='api.binance.com', port=443): Max retries exceeded with url: /api/v3/account?timestamp=1721606157559&signature=319427b6bed782f47f1e2f3f3c0d541d10f7b372e8e986b0b7aad0e881d01bce (Caused by NewConnectionError('<urllib3.connection.HTTPSConnection object at 0x7f2913066280>: Failed to establish a new connection: [Errno 111] Connection refused'))
[2024-07-21T23:56:02.338+0000] {taskinstance.py:1138} INFO - Marking task as FAILED. dag_id=crypto_pipeline, task_id=fetch_data, execution_date=20240720T222500, start_date=20240720T225403, end_date=20240721T235602
[2024-07-21T23:56:02.474+0000] {standard_task_runner.py:107} ERROR - Failed to execute job 533 for task fetch_data (HTTPSConnectionPool(host='api.binance.com', port=443): Max retries exceeded with url: /api/v3/account?timestamp=1721606157559&signature=319427b6bed782f47f1e2f3f3c0d541d10f7b372e8e986b0b7aad0e881d01bce (Caused by NewConnectionError('<urllib3.connection.HTTPSConnection object at 0x7f2913066280>: Failed to establish a new connection: [Errno 111] Connection refused')); 5975)
[2024-07-21T23:56:02.567+0000] {local_task_job_runner.py:234} INFO - Task exited with return code 1
[2024-07-21T23:56:02.694+0000] {taskinstance.py:3280} INFO - 0 downstream tasks scheduled from follow-on schedule check
