[2024-08-08T16:38:51.770+0000] {taskinstance.py:1956} INFO - Dependencies all met for dep_context=non-requeueable deps ti=<TaskInstance: crypto_pipeline.fetch_data scheduled__2024-08-08T16:15:00+00:00 [queued]>
[2024-08-08T16:38:51.801+0000] {taskinstance.py:1956} INFO - Dependencies all met for dep_context=requeueable deps ti=<TaskInstance: crypto_pipeline.fetch_data scheduled__2024-08-08T16:15:00+00:00 [queued]>
[2024-08-08T16:38:51.802+0000] {taskinstance.py:2170} INFO - Starting attempt 1 of 1
[2024-08-08T16:38:51.827+0000] {taskinstance.py:2191} INFO - Executing <Task(PythonOperator): fetch_data> on 2024-08-08 16:15:00+00:00
[2024-08-08T16:38:51.837+0000] {standard_task_runner.py:60} INFO - Started process 2776 to run task
[2024-08-08T16:38:51.841+0000] {standard_task_runner.py:87} INFO - Running: ['***', 'tasks', 'run', 'crypto_pipeline', 'fetch_data', 'scheduled__2024-08-08T16:15:00+00:00', '--job-id', '2745', '--raw', '--subdir', 'DAGS_FOLDER/crypto_pipeline_dag.py', '--cfg-path', '/tmp/tmpsy3x94_f']
[2024-08-08T16:38:51.843+0000] {standard_task_runner.py:88} INFO - Job 2745: Subtask fetch_data
[2024-08-08T16:38:51.921+0000] {task_command.py:423} INFO - Running <TaskInstance: crypto_pipeline.fetch_data scheduled__2024-08-08T16:15:00+00:00 [running]> on host 58dd90220664
[2024-08-08T16:38:52.055+0000] {taskinstance.py:2480} INFO - Exporting env vars: AIRFLOW_CTX_DAG_OWNER='***' AIRFLOW_CTX_DAG_ID='crypto_pipeline' AIRFLOW_CTX_TASK_ID='fetch_data' AIRFLOW_CTX_EXECUTION_DATE='2024-08-08T16:15:00+00:00' AIRFLOW_CTX_TRY_NUMBER='1' AIRFLOW_CTX_DAG_RUN_ID='scheduled__2024-08-08T16:15:00+00:00'
[2024-08-08T16:59:07.345+0000] {logging_mixin.py:188} INFO - Error: 400
[2024-08-08T16:59:07.346+0000] {logging_mixin.py:188} INFO - {"code":-1021,"msg":"Timestamp for this request is outside of the recvWindow."}
[2024-08-08T16:59:07.350+0000] {taskinstance.py:2698} ERROR - Task failed with exception
Traceback (most recent call last):
  File "/home/airflow/.local/lib/python3.8/site-packages/airflow/models/taskinstance.py", line 433, in _execute_task
    result = execute_callable(context=context, **execute_callable_kwargs)
  File "/home/airflow/.local/lib/python3.8/site-packages/airflow/operators/python.py", line 199, in execute
    return_value = self.execute_callable()
  File "/home/airflow/.local/lib/python3.8/site-packages/airflow/operators/python.py", line 216, in execute_callable
    return self.python_callable(*self.op_args, **self.op_kwargs)
  File "/opt/airflow/dags/crypto_pipeline_dag.py", line 28, in fetch_data_with_xcom
    df = fetch_data()
  File "/opt/airflow/Program.py", line 11, in fetch_data
    return generate_dataframe(api_key, signature_key)
  File "/opt/airflow/src/generate_data_frame.py", line 22, in generate_dataframe
    raise ValueError("Failed to fetch crypto amounts. Received None.")
ValueError: Failed to fetch crypto amounts. Received None.
[2024-08-08T16:59:07.370+0000] {taskinstance.py:1138} INFO - Marking task as FAILED. dag_id=crypto_pipeline, task_id=fetch_data, execution_date=20240808T161500, start_date=20240808T163851, end_date=20240808T165907
[2024-08-08T16:59:07.390+0000] {standard_task_runner.py:107} ERROR - Failed to execute job 2745 for task fetch_data (Failed to fetch crypto amounts. Received None.; 2776)
[2024-08-08T16:59:07.441+0000] {local_task_job_runner.py:234} INFO - Task exited with return code 1
[2024-08-08T16:59:07.459+0000] {taskinstance.py:3280} INFO - 0 downstream tasks scheduled from follow-on schedule check
