[2024-07-25T12:58:19.539+0000] {taskinstance.py:1956} INFO - Dependencies all met for dep_context=non-requeueable deps ti=<TaskInstance: crypto_pipeline.load_data scheduled__2024-07-24T19:35:00+00:00 [queued]>
[2024-07-25T12:58:19.588+0000] {taskinstance.py:1956} INFO - Dependencies all met for dep_context=requeueable deps ti=<TaskInstance: crypto_pipeline.load_data scheduled__2024-07-24T19:35:00+00:00 [queued]>
[2024-07-25T12:58:19.589+0000] {taskinstance.py:2170} INFO - Starting attempt 1 of 1
[2024-07-25T12:58:19.625+0000] {taskinstance.py:2191} INFO - Executing <Task(PythonOperator): load_data> on 2024-07-24 19:35:00+00:00
[2024-07-25T12:58:19.675+0000] {standard_task_runner.py:60} INFO - Started process 22518 to run task
[2024-07-25T12:58:19.683+0000] {standard_task_runner.py:87} INFO - Running: ['***', 'tasks', 'run', 'crypto_pipeline', 'load_data', 'scheduled__2024-07-24T19:35:00+00:00', '--job-id', '1159', '--raw', '--subdir', 'DAGS_FOLDER/crypto_pipeline_dag.py', '--cfg-path', '/tmp/tmp8zhzy77u']
[2024-07-25T12:58:19.687+0000] {standard_task_runner.py:88} INFO - Job 1159: Subtask load_data
[2024-07-25T12:58:19.859+0000] {task_command.py:423} INFO - Running <TaskInstance: crypto_pipeline.load_data scheduled__2024-07-24T19:35:00+00:00 [running]> on host 58dd90220664
[2024-07-25T12:58:20.267+0000] {taskinstance.py:2480} INFO - Exporting env vars: AIRFLOW_CTX_DAG_OWNER='***' AIRFLOW_CTX_DAG_ID='crypto_pipeline' AIRFLOW_CTX_TASK_ID='load_data' AIRFLOW_CTX_EXECUTION_DATE='2024-07-24T19:35:00+00:00' AIRFLOW_CTX_TRY_NUMBER='1' AIRFLOW_CTX_DAG_RUN_ID='scheduled__2024-07-24T19:35:00+00:00'
[2024-07-25T12:58:20.505+0000] {taskinstance.py:2698} ERROR - Task failed with exception
Traceback (most recent call last):
  File "/home/airflow/.local/lib/python3.8/site-packages/airflow/models/taskinstance.py", line 433, in _execute_task
    result = execute_callable(context=context, **execute_callable_kwargs)
  File "/home/airflow/.local/lib/python3.8/site-packages/airflow/operators/python.py", line 199, in execute
    return_value = self.execute_callable()
  File "/home/airflow/.local/lib/python3.8/site-packages/airflow/operators/python.py", line 216, in execute_callable
    return self.python_callable(*self.op_args, **self.op_kwargs)
  File "/opt/airflow/dags/crypto_pipeline_dag.py", line 43, in load_data_with_xcom
    load_data(
  File "/opt/airflow/Program.py", line 70, in load_data
    fetch_and_load(host, port, database, user, password,
  File "/opt/airflow/src/fetch_and_load.py", line 22, in fetch_and_load
    conn = psycopg2.connect (
  File "/home/airflow/.local/lib/python3.8/site-packages/psycopg2/__init__.py", line 122, in connect
    conn = _connect(dsn, connection_factory=connection_factory, **kwasync)
psycopg2.OperationalError: connection to server at "34.162.73.30", port 5432 failed: Connection refused
	Is the server running on that host and accepting TCP/IP connections?

[2024-07-25T12:58:20.948+0000] {taskinstance.py:1138} INFO - Marking task as FAILED. dag_id=crypto_pipeline, task_id=load_data, execution_date=20240724T193500, start_date=20240725T125819, end_date=20240725T125820
[2024-07-25T12:58:21.048+0000] {standard_task_runner.py:107} ERROR - Failed to execute job 1159 for task load_data (connection to server at "34.162.73.30", port 5432 failed: Connection refused
	Is the server running on that host and accepting TCP/IP connections?
; 22518)
[2024-07-25T12:58:21.105+0000] {local_task_job_runner.py:234} INFO - Task exited with return code 1
[2024-07-25T12:58:21.153+0000] {taskinstance.py:3280} INFO - 0 downstream tasks scheduled from follow-on schedule check
