[2024-07-22T12:51:17.230+0000] {taskinstance.py:1956} INFO - Dependencies all met for dep_context=non-requeueable deps ti=<TaskInstance: crypto_pipeline.fetch_data scheduled__2024-07-22T12:45:00+00:00 [queued]>
[2024-07-22T12:51:17.326+0000] {taskinstance.py:1956} INFO - Dependencies all met for dep_context=requeueable deps ti=<TaskInstance: crypto_pipeline.fetch_data scheduled__2024-07-22T12:45:00+00:00 [queued]>
[2024-07-22T12:51:17.383+0000] {taskinstance.py:2170} INFO - Starting attempt 1 of 1
[2024-07-22T12:51:17.687+0000] {taskinstance.py:2191} INFO - Executing <Task(PythonOperator): fetch_data> on 2024-07-22 12:45:00+00:00
[2024-07-22T12:51:17.815+0000] {standard_task_runner.py:60} INFO - Started process 6289 to run task
[2024-07-22T12:51:17.849+0000] {standard_task_runner.py:87} INFO - Running: ['***', 'tasks', 'run', 'crypto_pipeline', 'fetch_data', 'scheduled__2024-07-22T12:45:00+00:00', '--job-id', '548', '--raw', '--subdir', 'DAGS_FOLDER/crypto_pipeline_dag.py', '--cfg-path', '/tmp/tmpn_p6yj0e']
[2024-07-22T12:51:17.872+0000] {standard_task_runner.py:88} INFO - Job 548: Subtask fetch_data
[2024-07-22T12:51:18.110+0000] {task_command.py:423} INFO - Running <TaskInstance: crypto_pipeline.fetch_data scheduled__2024-07-22T12:45:00+00:00 [running]> on host 58dd90220664
[2024-07-22T12:51:18.497+0000] {taskinstance.py:2480} INFO - Exporting env vars: AIRFLOW_CTX_DAG_OWNER='***' AIRFLOW_CTX_DAG_ID='crypto_pipeline' AIRFLOW_CTX_TASK_ID='fetch_data' AIRFLOW_CTX_EXECUTION_DATE='2024-07-22T12:45:00+00:00' AIRFLOW_CTX_TRY_NUMBER='1' AIRFLOW_CTX_DAG_RUN_ID='scheduled__2024-07-22T12:45:00+00:00'
[2024-07-22T12:51:19.168+0000] {taskinstance.py:2698} ERROR - Task failed with exception
Traceback (most recent call last):
  File "/home/airflow/.local/lib/python3.8/site-packages/urllib3/connectionpool.py", line 715, in urlopen
    httplib_response = self._make_request(
  File "/home/airflow/.local/lib/python3.8/site-packages/urllib3/connectionpool.py", line 404, in _make_request
    self._validate_conn(conn)
  File "/home/airflow/.local/lib/python3.8/site-packages/urllib3/connectionpool.py", line 1058, in _validate_conn
    conn.connect()
  File "/home/airflow/.local/lib/python3.8/site-packages/urllib3/connection.py", line 419, in connect
    self.sock = ssl_wrap_socket(
  File "/home/airflow/.local/lib/python3.8/site-packages/urllib3/util/ssl_.py", line 449, in ssl_wrap_socket
    ssl_sock = _ssl_wrap_socket_impl(
  File "/home/airflow/.local/lib/python3.8/site-packages/urllib3/util/ssl_.py", line 493, in _ssl_wrap_socket_impl
    return ssl_context.wrap_socket(sock, server_hostname=server_hostname)
  File "/usr/local/lib/python3.8/ssl.py", line 500, in wrap_socket
    return self.sslsocket_class._create(
  File "/usr/local/lib/python3.8/ssl.py", line 1073, in _create
    self.do_handshake()
  File "/usr/local/lib/python3.8/ssl.py", line 1342, in do_handshake
    self._sslobj.do_handshake()
ssl.SSLZeroReturnError: TLS/SSL connection has been closed (EOF) (_ssl.c:1131)

During handling of the above exception, another exception occurred:

Traceback (most recent call last):
  File "/home/airflow/.local/lib/python3.8/site-packages/requests/adapters.py", line 486, in send
    resp = conn.urlopen(
  File "/home/airflow/.local/lib/python3.8/site-packages/urllib3/connectionpool.py", line 799, in urlopen
    retries = retries.increment(
  File "/home/airflow/.local/lib/python3.8/site-packages/urllib3/util/retry.py", line 592, in increment
    raise MaxRetryError(_pool, url, error or ResponseError(cause))
urllib3.exceptions.MaxRetryError: HTTPSConnectionPool(host='api.binance.com', port=443): Max retries exceeded with url: /api/v3/account?timestamp=1721652678689&signature=ccaba560cb808b5f09b8455e66a4c5d3182391a65102292939582aac94d0fd2c (Caused by SSLError(SSLZeroReturnError(6, 'TLS/SSL connection has been closed (EOF) (_ssl.c:1131)')))

During handling of the above exception, another exception occurred:

Traceback (most recent call last):
  File "/home/airflow/.local/lib/python3.8/site-packages/airflow/models/taskinstance.py", line 433, in _execute_task
    result = execute_callable(context=context, **execute_callable_kwargs)
  File "/home/airflow/.local/lib/python3.8/site-packages/airflow/operators/python.py", line 199, in execute
    return_value = self.execute_callable()
  File "/home/airflow/.local/lib/python3.8/site-packages/airflow/operators/python.py", line 216, in execute_callable
    return self.python_callable(*self.op_args, **self.op_kwargs)
  File "/opt/airflow/dags/crypto_pipeline_dag.py", line 28, in fetch_data_with_xcom
    df = fetch_data()
  File "/opt/airflow/Program.py", line 11, in fetch_data
    return generate_dataframe(api_key, signature_key)
  File "/opt/airflow/src/generate_data_frame.py", line 17, in generate_dataframe
    crypto_amounts = get_crypto_amounts(api_key, signature_key)
  File "/opt/airflow/src/extract_crypto_amounts.py", line 20, in get_crypto_amounts
    response = requests.get(url, headers=headers)
  File "/home/airflow/.local/lib/python3.8/site-packages/requests/api.py", line 73, in get
    return request("get", url, params=params, **kwargs)
  File "/home/airflow/.local/lib/python3.8/site-packages/requests/api.py", line 59, in request
    return session.request(method=method, url=url, **kwargs)
  File "/home/airflow/.local/lib/python3.8/site-packages/requests/sessions.py", line 589, in request
    resp = self.send(prep, **send_kwargs)
  File "/home/airflow/.local/lib/python3.8/site-packages/requests/sessions.py", line 703, in send
    r = adapter.send(request, **kwargs)
  File "/home/airflow/.local/lib/python3.8/site-packages/requests/adapters.py", line 517, in send
    raise SSLError(e, request=request)
requests.exceptions.SSLError: HTTPSConnectionPool(host='api.binance.com', port=443): Max retries exceeded with url: /api/v3/account?timestamp=1721652678689&signature=ccaba560cb808b5f09b8455e66a4c5d3182391a65102292939582aac94d0fd2c (Caused by SSLError(SSLZeroReturnError(6, 'TLS/SSL connection has been closed (EOF) (_ssl.c:1131)')))
[2024-07-22T12:51:19.378+0000] {taskinstance.py:1138} INFO - Marking task as FAILED. dag_id=crypto_pipeline, task_id=fetch_data, execution_date=20240722T124500, start_date=20240722T125117, end_date=20240722T125119
[2024-07-22T12:51:19.442+0000] {standard_task_runner.py:107} ERROR - Failed to execute job 548 for task fetch_data (HTTPSConnectionPool(host='api.binance.com', port=443): Max retries exceeded with url: /api/v3/account?timestamp=1721652678689&signature=ccaba560cb808b5f09b8455e66a4c5d3182391a65102292939582aac94d0fd2c (Caused by SSLError(SSLZeroReturnError(6, 'TLS/SSL connection has been closed (EOF) (_ssl.c:1131)'))); 6289)
[2024-07-22T12:51:19.538+0000] {local_task_job_runner.py:234} INFO - Task exited with return code 1
[2024-07-22T12:51:19.602+0000] {taskinstance.py:3280} INFO - 0 downstream tasks scheduled from follow-on schedule check
