[2024-07-19T18:25:07.133+0000] {taskinstance.py:1956} INFO - Dependencies all met for dep_context=non-requeueable deps ti=<TaskInstance: crypto_pipeline.load_data scheduled__2024-07-19T18:20:00+00:00 [queued]>
[2024-07-19T18:25:07.139+0000] {taskinstance.py:1956} INFO - Dependencies all met for dep_context=requeueable deps ti=<TaskInstance: crypto_pipeline.load_data scheduled__2024-07-19T18:20:00+00:00 [queued]>
[2024-07-19T18:25:07.140+0000] {taskinstance.py:2170} INFO - Starting attempt 1 of 1
[2024-07-19T18:25:07.153+0000] {taskinstance.py:2191} INFO - Executing <Task(PythonOperator): load_data> on 2024-07-19 18:20:00+00:00
[2024-07-19T18:25:07.158+0000] {standard_task_runner.py:60} INFO - Started process 483 to run task
[2024-07-19T18:25:07.161+0000] {standard_task_runner.py:87} INFO - Running: ['***', 'tasks', 'run', 'crypto_pipeline', 'load_data', 'scheduled__2024-07-19T18:20:00+00:00', '--job-id', '314', '--raw', '--subdir', 'DAGS_FOLDER/crypto_pipeline_dag.py', '--cfg-path', '/tmp/tmpqo9zqhhq']
[2024-07-19T18:25:07.162+0000] {standard_task_runner.py:88} INFO - Job 314: Subtask load_data
[2024-07-19T18:25:07.200+0000] {task_command.py:423} INFO - Running <TaskInstance: crypto_pipeline.load_data scheduled__2024-07-19T18:20:00+00:00 [running]> on host 58dd90220664
[2024-07-19T18:25:07.257+0000] {taskinstance.py:2480} INFO - Exporting env vars: AIRFLOW_CTX_DAG_OWNER='***' AIRFLOW_CTX_DAG_ID='crypto_pipeline' AIRFLOW_CTX_TASK_ID='load_data' AIRFLOW_CTX_EXECUTION_DATE='2024-07-19T18:20:00+00:00' AIRFLOW_CTX_TRY_NUMBER='1' AIRFLOW_CTX_DAG_RUN_ID='scheduled__2024-07-19T18:20:00+00:00'
[2024-07-19T18:25:07.266+0000] {taskinstance.py:2698} ERROR - Task failed with exception
Traceback (most recent call last):
  File "/home/airflow/.local/lib/python3.8/site-packages/airflow/models/taskinstance.py", line 433, in _execute_task
    result = execute_callable(context=context, **execute_callable_kwargs)
  File "/home/airflow/.local/lib/python3.8/site-packages/airflow/operators/python.py", line 199, in execute
    return_value = self.execute_callable()
  File "/home/airflow/.local/lib/python3.8/site-packages/airflow/operators/python.py", line 216, in execute_callable
    return self.python_callable(*self.op_args, **self.op_kwargs)
  File "/opt/airflow/dags/crypto_pipeline_dag.py", line 65, in load_data_with_xcom
    load_data(data)
TypeError: load_data() missing 14 required positional arguments: 'btcusdt_rate', 'ethusdt_rate', 'solusdt_rate', 'btcbrl_rate', 'ethbrl_rate', 'solbrl_rate', 'btcusdt_total', 'ethusdt_total', 'solusdt_total', 'btcbrl_total', 'ethbrl_total', 'solbrl_total', 'brl_total', and 'usdt_total'
[2024-07-19T18:25:07.274+0000] {taskinstance.py:1138} INFO - Marking task as FAILED. dag_id=crypto_pipeline, task_id=load_data, execution_date=20240719T182000, start_date=20240719T182507, end_date=20240719T182507
[2024-07-19T18:25:07.284+0000] {standard_task_runner.py:107} ERROR - Failed to execute job 314 for task load_data (load_data() missing 14 required positional arguments: 'btcusdt_rate', 'ethusdt_rate', 'solusdt_rate', 'btcbrl_rate', 'ethbrl_rate', 'solbrl_rate', 'btcusdt_total', 'ethusdt_total', 'solusdt_total', 'btcbrl_total', 'ethbrl_total', 'solbrl_total', 'brl_total', and 'usdt_total'; 483)
[2024-07-19T18:25:07.293+0000] {local_task_job_runner.py:234} INFO - Task exited with return code 1
[2024-07-19T18:25:07.306+0000] {taskinstance.py:3280} INFO - 0 downstream tasks scheduled from follow-on schedule check
