[2024-07-27T15:58:58.559+0000] {taskinstance.py:1956} INFO - Dependencies all met for dep_context=non-requeueable deps ti=<TaskInstance: crypto_pipeline.fetch_data scheduled__2024-07-27T14:05:00+00:00 [queued]>
[2024-07-27T15:58:58.571+0000] {taskinstance.py:1956} INFO - Dependencies all met for dep_context=requeueable deps ti=<TaskInstance: crypto_pipeline.fetch_data scheduled__2024-07-27T14:05:00+00:00 [queued]>
[2024-07-27T15:58:58.571+0000] {taskinstance.py:2170} INFO - Starting attempt 1 of 1
[2024-07-27T16:18:05.016+0000] {taskinstance.py:2191} INFO - Executing <Task(PythonOperator): fetch_data> on 2024-07-27 14:05:00+00:00
[2024-07-27T16:18:05.049+0000] {standard_task_runner.py:60} INFO - Started process 28880 to run task
[2024-07-27T16:18:05.052+0000] {standard_task_runner.py:87} INFO - Running: ['***', 'tasks', 'run', 'crypto_pipeline', 'fetch_data', 'scheduled__2024-07-27T14:05:00+00:00', '--job-id', '1427', '--raw', '--subdir', 'DAGS_FOLDER/crypto_pipeline_dag.py', '--cfg-path', '/tmp/tmptguxomrp']
[2024-07-27T16:18:05.076+0000] {standard_task_runner.py:88} INFO - Job 1427: Subtask fetch_data
[2024-07-27T16:18:05.169+0000] {task_command.py:423} INFO - Running <TaskInstance: crypto_pipeline.fetch_data scheduled__2024-07-27T14:05:00+00:00 [running]> on host 58dd90220664
[2024-07-27T16:18:05.336+0000] {taskinstance.py:2480} INFO - Exporting env vars: AIRFLOW_CTX_DAG_OWNER='***' AIRFLOW_CTX_DAG_ID='crypto_pipeline' AIRFLOW_CTX_TASK_ID='fetch_data' AIRFLOW_CTX_EXECUTION_DATE='2024-07-27T14:05:00+00:00' AIRFLOW_CTX_TRY_NUMBER='1' AIRFLOW_CTX_DAG_RUN_ID='scheduled__2024-07-27T14:05:00+00:00'
[2024-07-27T16:29:05.897+0000] {taskinstance.py:2698} ERROR - Task failed with exception
Traceback (most recent call last):
  File "/home/airflow/.local/lib/python3.8/site-packages/urllib3/connectionpool.py", line 715, in urlopen
    httplib_response = self._make_request(
  File "/home/airflow/.local/lib/python3.8/site-packages/urllib3/connectionpool.py", line 467, in _make_request
    six.raise_from(e, None)
  File "<string>", line 3, in raise_from
  File "/home/airflow/.local/lib/python3.8/site-packages/urllib3/connectionpool.py", line 462, in _make_request
    httplib_response = conn.getresponse()
  File "/usr/local/lib/python3.8/http/client.py", line 1348, in getresponse
    response.begin()
  File "/usr/local/lib/python3.8/http/client.py", line 316, in begin
    version, status, reason = self._read_status()
  File "/usr/local/lib/python3.8/http/client.py", line 285, in _read_status
    raise RemoteDisconnected("Remote end closed connection without"
http.client.RemoteDisconnected: Remote end closed connection without response

During handling of the above exception, another exception occurred:

Traceback (most recent call last):
  File "/home/airflow/.local/lib/python3.8/site-packages/requests/adapters.py", line 486, in send
    resp = conn.urlopen(
  File "/home/airflow/.local/lib/python3.8/site-packages/urllib3/connectionpool.py", line 799, in urlopen
    retries = retries.increment(
  File "/home/airflow/.local/lib/python3.8/site-packages/urllib3/util/retry.py", line 550, in increment
    raise six.reraise(type(error), error, _stacktrace)
  File "/home/airflow/.local/lib/python3.8/site-packages/urllib3/packages/six.py", line 769, in reraise
    raise value.with_traceback(tb)
  File "/home/airflow/.local/lib/python3.8/site-packages/urllib3/connectionpool.py", line 715, in urlopen
    httplib_response = self._make_request(
  File "/home/airflow/.local/lib/python3.8/site-packages/urllib3/connectionpool.py", line 467, in _make_request
    six.raise_from(e, None)
  File "<string>", line 3, in raise_from
  File "/home/airflow/.local/lib/python3.8/site-packages/urllib3/connectionpool.py", line 462, in _make_request
    httplib_response = conn.getresponse()
  File "/usr/local/lib/python3.8/http/client.py", line 1348, in getresponse
    response.begin()
  File "/usr/local/lib/python3.8/http/client.py", line 316, in begin
    version, status, reason = self._read_status()
  File "/usr/local/lib/python3.8/http/client.py", line 285, in _read_status
    raise RemoteDisconnected("Remote end closed connection without"
urllib3.exceptions.ProtocolError: ('Connection aborted.', RemoteDisconnected('Remote end closed connection without response'))

During handling of the above exception, another exception occurred:

Traceback (most recent call last):
  File "/home/airflow/.local/lib/python3.8/site-packages/airflow/models/taskinstance.py", line 433, in _execute_task
    result = execute_callable(context=context, **execute_callable_kwargs)
  File "/home/airflow/.local/lib/python3.8/site-packages/airflow/operators/python.py", line 199, in execute
    return_value = self.execute_callable()
  File "/home/airflow/.local/lib/python3.8/site-packages/airflow/operators/python.py", line 216, in execute_callable
    return self.python_callable(*self.op_args, **self.op_kwargs)
  File "/opt/airflow/dags/crypto_pipeline_dag.py", line 28, in fetch_data_with_xcom
    df = fetch_data()
  File "/opt/airflow/Program.py", line 11, in fetch_data
    return generate_dataframe(api_key, signature_key)
  File "/opt/airflow/src/generate_data_frame.py", line 17, in generate_dataframe
    crypto_amounts = get_crypto_amounts(api_key, signature_key)
  File "/opt/airflow/src/extract_crypto_amounts.py", line 20, in get_crypto_amounts
    response = requests.get(url, headers=headers)
  File "/home/airflow/.local/lib/python3.8/site-packages/requests/api.py", line 73, in get
    return request("get", url, params=params, **kwargs)
  File "/home/airflow/.local/lib/python3.8/site-packages/requests/api.py", line 59, in request
    return session.request(method=method, url=url, **kwargs)
  File "/home/airflow/.local/lib/python3.8/site-packages/requests/sessions.py", line 589, in request
    resp = self.send(prep, **send_kwargs)
  File "/home/airflow/.local/lib/python3.8/site-packages/requests/sessions.py", line 703, in send
    r = adapter.send(request, **kwargs)
  File "/home/airflow/.local/lib/python3.8/site-packages/requests/adapters.py", line 501, in send
    raise ConnectionError(err, request=request)
requests.exceptions.ConnectionError: ('Connection aborted.', RemoteDisconnected('Remote end closed connection without response'))
[2024-07-27T16:29:06.175+0000] {taskinstance.py:1138} INFO - Marking task as FAILED. dag_id=crypto_pipeline, task_id=fetch_data, execution_date=20240727T140500, start_date=20240727T155858, end_date=20240727T162906
[2024-07-27T16:29:06.207+0000] {standard_task_runner.py:107} ERROR - Failed to execute job 1427 for task fetch_data (('Connection aborted.', RemoteDisconnected('Remote end closed connection without response')); 28880)
[2024-07-27T16:29:06.232+0000] {local_task_job_runner.py:234} INFO - Task exited with return code 1
[2024-07-27T16:29:06.273+0000] {taskinstance.py:3280} INFO - 0 downstream tasks scheduled from follow-on schedule check
