[2024-07-19T18:27:14.715+0000] {taskinstance.py:1956} INFO - Dependencies all met for dep_context=non-requeueable deps ti=<TaskInstance: crypto_pipeline.load_data manual__2024-07-19T18:27:06.785391+00:00 [queued]>
[2024-07-19T18:27:14.731+0000] {taskinstance.py:1956} INFO - Dependencies all met for dep_context=requeueable deps ti=<TaskInstance: crypto_pipeline.load_data manual__2024-07-19T18:27:06.785391+00:00 [queued]>
[2024-07-19T18:27:14.732+0000] {taskinstance.py:2170} INFO - Starting attempt 1 of 1
[2024-07-19T18:27:14.751+0000] {taskinstance.py:2191} INFO - Executing <Task(PythonOperator): load_data> on 2024-07-19 18:27:06.785391+00:00
[2024-07-19T18:27:14.760+0000] {standard_task_runner.py:60} INFO - Started process 541 to run task
[2024-07-19T18:27:14.765+0000] {standard_task_runner.py:87} INFO - Running: ['***', 'tasks', 'run', 'crypto_pipeline', 'load_data', 'manual__2024-07-19T18:27:06.785391+00:00', '--job-id', '317', '--raw', '--subdir', 'DAGS_FOLDER/crypto_pipeline_dag.py', '--cfg-path', '/tmp/tmpn53kuict']
[2024-07-19T18:27:14.768+0000] {standard_task_runner.py:88} INFO - Job 317: Subtask load_data
[2024-07-19T18:27:14.825+0000] {task_command.py:423} INFO - Running <TaskInstance: crypto_pipeline.load_data manual__2024-07-19T18:27:06.785391+00:00 [running]> on host 58dd90220664
[2024-07-19T18:27:14.904+0000] {taskinstance.py:2480} INFO - Exporting env vars: AIRFLOW_CTX_DAG_OWNER='***' AIRFLOW_CTX_DAG_ID='crypto_pipeline' AIRFLOW_CTX_TASK_ID='load_data' AIRFLOW_CTX_EXECUTION_DATE='2024-07-19T18:27:06.785391+00:00' AIRFLOW_CTX_TRY_NUMBER='1' AIRFLOW_CTX_DAG_RUN_ID='manual__2024-07-19T18:27:06.785391+00:00'
[2024-07-19T18:27:14.940+0000] {taskinstance.py:2698} ERROR - Task failed with exception
Traceback (most recent call last):
  File "/home/airflow/.local/lib/python3.8/site-packages/airflow/models/taskinstance.py", line 433, in _execute_task
    result = execute_callable(context=context, **execute_callable_kwargs)
  File "/home/airflow/.local/lib/python3.8/site-packages/airflow/operators/python.py", line 199, in execute
    return_value = self.execute_callable()
  File "/home/airflow/.local/lib/python3.8/site-packages/airflow/operators/python.py", line 216, in execute_callable
    return self.python_callable(*self.op_args, **self.op_kwargs)
  File "/opt/airflow/dags/crypto_pipeline_dag.py", line 65, in load_data_with_xcom
    load_data(data)
  File "/opt/airflow/Program.py", line 103, in load_data
    fetch_and_load(host, port, database, user, password, **data)
TypeError: fetch_and_load() argument after ** must be a mapping, not NoneType
[2024-07-19T18:27:14.966+0000] {taskinstance.py:1138} INFO - Marking task as FAILED. dag_id=crypto_pipeline, task_id=load_data, execution_date=20240719T182706, start_date=20240719T182714, end_date=20240719T182714
[2024-07-19T18:27:14.998+0000] {standard_task_runner.py:107} ERROR - Failed to execute job 317 for task load_data (fetch_and_load() argument after ** must be a mapping, not NoneType; 541)
[2024-07-19T18:27:15.018+0000] {local_task_job_runner.py:234} INFO - Task exited with return code 1
[2024-07-19T18:27:15.038+0000] {taskinstance.py:3280} INFO - 0 downstream tasks scheduled from follow-on schedule check
