[2024-07-19T20:14:23.872+0000] {taskinstance.py:1956} INFO - Dependencies all met for dep_context=non-requeueable deps ti=<TaskInstance: crypto_pipeline.load_data scheduled__2024-07-19T19:30:00+00:00 [queued]>
[2024-07-19T20:14:23.889+0000] {taskinstance.py:1956} INFO - Dependencies all met for dep_context=requeueable deps ti=<TaskInstance: crypto_pipeline.load_data scheduled__2024-07-19T19:30:00+00:00 [queued]>
[2024-07-19T20:14:23.890+0000] {taskinstance.py:2170} INFO - Starting attempt 1 of 1
[2024-07-19T20:14:23.914+0000] {taskinstance.py:2191} INFO - Executing <Task(PythonOperator): load_data> on 2024-07-19 19:30:00+00:00
[2024-07-19T20:14:23.925+0000] {standard_task_runner.py:60} INFO - Started process 1498 to run task
[2024-07-19T20:14:23.930+0000] {standard_task_runner.py:87} INFO - Running: ['***', 'tasks', 'run', 'crypto_pipeline', 'load_data', 'scheduled__2024-07-19T19:30:00+00:00', '--job-id', '370', '--raw', '--subdir', 'DAGS_FOLDER/crypto_pipeline_dag.py', '--cfg-path', '/tmp/tmpua0xbdsn']
[2024-07-19T20:14:23.933+0000] {standard_task_runner.py:88} INFO - Job 370: Subtask load_data
[2024-07-19T20:14:24.009+0000] {task_command.py:423} INFO - Running <TaskInstance: crypto_pipeline.load_data scheduled__2024-07-19T19:30:00+00:00 [running]> on host 58dd90220664
[2024-07-19T20:14:24.122+0000] {taskinstance.py:2480} INFO - Exporting env vars: AIRFLOW_CTX_DAG_OWNER='***' AIRFLOW_CTX_DAG_ID='crypto_pipeline' AIRFLOW_CTX_TASK_ID='load_data' AIRFLOW_CTX_EXECUTION_DATE='2024-07-19T19:30:00+00:00' AIRFLOW_CTX_TRY_NUMBER='1' AIRFLOW_CTX_DAG_RUN_ID='scheduled__2024-07-19T19:30:00+00:00'
[2024-07-19T20:14:25.589+0000] {taskinstance.py:2698} ERROR - Task failed with exception
Traceback (most recent call last):
  File "/home/airflow/.local/lib/python3.8/site-packages/airflow/models/taskinstance.py", line 433, in _execute_task
    result = execute_callable(context=context, **execute_callable_kwargs)
  File "/home/airflow/.local/lib/python3.8/site-packages/airflow/operators/python.py", line 199, in execute
    return_value = self.execute_callable()
  File "/home/airflow/.local/lib/python3.8/site-packages/airflow/operators/python.py", line 216, in execute_callable
    return self.python_callable(*self.op_args, **self.op_kwargs)
  File "/opt/airflow/dags/crypto_pipeline_dag.py", line 43, in load_data_with_xcom
    load_data(
  File "/opt/airflow/Program.py", line 70, in load_data
    fetch_and_load(host, port, database, user, password,
  File "/opt/airflow/src/fetch_and_load.py", line 22, in fetch_and_load
    conn = psycopg2.connect (
  File "/home/airflow/.local/lib/python3.8/site-packages/psycopg2/__init__.py", line 122, in connect
    conn = _connect(dsn, connection_factory=connection_factory, **kwasync)
psycopg2.OperationalError: connection to server at "34.162.73.30", port 5432 failed: SSL SYSCALL error: Success
connection to server at "34.162.73.30", port 5432 failed: Connection refused
	Is the server running on that host and accepting TCP/IP connections?

[2024-07-20T14:07:56.901+0000] {taskinstance.py:1138} INFO - Marking task as FAILED. dag_id=crypto_pipeline, task_id=load_data, execution_date=20240719T193000, start_date=20240719T201423, end_date=20240720T140756
[2024-07-20T14:07:56.954+0000] {standard_task_runner.py:107} ERROR - Failed to execute job 370 for task load_data (connection to server at "34.162.73.30", port 5432 failed: SSL SYSCALL error: Success
connection to server at "34.162.73.30", port 5432 failed: Connection refused
	Is the server running on that host and accepting TCP/IP connections?
; 1498)
[2024-07-20T14:07:57.042+0000] {local_task_job_runner.py:234} INFO - Task exited with return code 1
[2024-07-20T14:07:57.101+0000] {taskinstance.py:3280} INFO - 0 downstream tasks scheduled from follow-on schedule check
