[2024-07-19T18:37:54.081+0000] {taskinstance.py:1956} INFO - Dependencies all met for dep_context=non-requeueable deps ti=<TaskInstance: crypto_pipeline.process_data manual__2024-07-19T18:37:48.185402+00:00 [queued]>
[2024-07-19T18:37:54.093+0000] {taskinstance.py:1956} INFO - Dependencies all met for dep_context=requeueable deps ti=<TaskInstance: crypto_pipeline.process_data manual__2024-07-19T18:37:48.185402+00:00 [queued]>
[2024-07-19T18:37:54.095+0000] {taskinstance.py:2170} INFO - Starting attempt 1 of 1
[2024-07-19T18:37:54.117+0000] {taskinstance.py:2191} INFO - Executing <Task(PythonOperator): process_data> on 2024-07-19 18:37:48.185402+00:00
[2024-07-19T18:37:54.126+0000] {standard_task_runner.py:60} INFO - Started process 860 to run task
[2024-07-19T18:37:54.130+0000] {standard_task_runner.py:87} INFO - Running: ['***', 'tasks', 'run', 'crypto_pipeline', 'process_data', 'manual__2024-07-19T18:37:48.185402+00:00', '--job-id', '336', '--raw', '--subdir', 'DAGS_FOLDER/crypto_pipeline_dag.py', '--cfg-path', '/tmp/tmpqqcquhdr']
[2024-07-19T18:37:54.132+0000] {standard_task_runner.py:88} INFO - Job 336: Subtask process_data
[2024-07-19T18:37:54.175+0000] {task_command.py:423} INFO - Running <TaskInstance: crypto_pipeline.process_data manual__2024-07-19T18:37:48.185402+00:00 [running]> on host 58dd90220664
[2024-07-19T18:37:54.241+0000] {taskinstance.py:2480} INFO - Exporting env vars: AIRFLOW_CTX_DAG_OWNER='***' AIRFLOW_CTX_DAG_ID='crypto_pipeline' AIRFLOW_CTX_TASK_ID='process_data' AIRFLOW_CTX_EXECUTION_DATE='2024-07-19T18:37:48.185402+00:00' AIRFLOW_CTX_TRY_NUMBER='1' AIRFLOW_CTX_DAG_RUN_ID='manual__2024-07-19T18:37:48.185402+00:00'
[2024-07-19T18:37:54.251+0000] {taskinstance.py:2698} ERROR - Task failed with exception
Traceback (most recent call last):
  File "/home/airflow/.local/lib/python3.8/site-packages/airflow/models/taskinstance.py", line 433, in _execute_task
    result = execute_callable(context=context, **execute_callable_kwargs)
  File "/home/airflow/.local/lib/python3.8/site-packages/airflow/operators/python.py", line 199, in execute
    return_value = self.execute_callable()
  File "/home/airflow/.local/lib/python3.8/site-packages/airflow/operators/python.py", line 216, in execute_callable
    return self.python_callable(*self.op_args, **self.op_kwargs)
  File "/opt/airflow/dags/crypto_pipeline_dag.py", line 63, in process_data_with_xcom
    df = pd.DataFrame(df_dict)
NameError: name 'pd' is not defined
[2024-07-19T18:37:54.260+0000] {taskinstance.py:1138} INFO - Marking task as FAILED. dag_id=crypto_pipeline, task_id=process_data, execution_date=20240719T183748, start_date=20240719T183754, end_date=20240719T183754
[2024-07-19T18:37:54.270+0000] {standard_task_runner.py:107} ERROR - Failed to execute job 336 for task process_data (name 'pd' is not defined; 860)
[2024-07-19T18:37:54.302+0000] {local_task_job_runner.py:234} INFO - Task exited with return code 1
[2024-07-19T18:37:54.319+0000] {taskinstance.py:3280} INFO - 0 downstream tasks scheduled from follow-on schedule check
