[2024-07-27T23:04:17.821+0000] {taskinstance.py:1956} INFO - Dependencies all met for dep_context=non-requeueable deps ti=<TaskInstance: crypto_pipeline.fetch_data scheduled__2024-07-27T22:45:00+00:00 [queued]>
[2024-07-27T23:04:17.829+0000] {taskinstance.py:1956} INFO - Dependencies all met for dep_context=requeueable deps ti=<TaskInstance: crypto_pipeline.fetch_data scheduled__2024-07-27T22:45:00+00:00 [queued]>
[2024-07-27T23:04:17.830+0000] {taskinstance.py:2170} INFO - Starting attempt 1 of 1
[2024-07-27T23:04:17.844+0000] {taskinstance.py:2191} INFO - Executing <Task(PythonOperator): fetch_data> on 2024-07-27 22:45:00+00:00
[2024-07-27T23:04:17.852+0000] {standard_task_runner.py:60} INFO - Started process 29002 to run task
[2024-07-27T23:04:17.855+0000] {standard_task_runner.py:87} INFO - Running: ['***', 'tasks', 'run', 'crypto_pipeline', 'fetch_data', 'scheduled__2024-07-27T22:45:00+00:00', '--job-id', '1440', '--raw', '--subdir', 'DAGS_FOLDER/crypto_pipeline_dag.py', '--cfg-path', '/tmp/tmp9i_x84qk']
[2024-07-27T23:04:17.856+0000] {standard_task_runner.py:88} INFO - Job 1440: Subtask fetch_data
[2024-07-27T23:04:17.902+0000] {task_command.py:423} INFO - Running <TaskInstance: crypto_pipeline.fetch_data scheduled__2024-07-27T22:45:00+00:00 [running]> on host 58dd90220664
[2024-07-27T23:04:17.988+0000] {taskinstance.py:2480} INFO - Exporting env vars: AIRFLOW_CTX_DAG_OWNER='***' AIRFLOW_CTX_DAG_ID='crypto_pipeline' AIRFLOW_CTX_TASK_ID='fetch_data' AIRFLOW_CTX_EXECUTION_DATE='2024-07-27T22:45:00+00:00' AIRFLOW_CTX_TRY_NUMBER='1' AIRFLOW_CTX_DAG_RUN_ID='scheduled__2024-07-27T22:45:00+00:00'
[2024-07-27T23:06:02.750+0000] {taskinstance.py:2698} ERROR - Task failed with exception
Traceback (most recent call last):
  File "/home/airflow/.local/lib/python3.8/site-packages/urllib3/connection.py", line 174, in _new_conn
    conn = connection.create_connection(
  File "/home/airflow/.local/lib/python3.8/site-packages/urllib3/util/connection.py", line 72, in create_connection
    for res in socket.getaddrinfo(host, port, family, socket.SOCK_STREAM):
  File "/usr/local/lib/python3.8/socket.py", line 918, in getaddrinfo
    for res in _socket.getaddrinfo(host, port, family, type, proto, flags):
socket.gaierror: [Errno -2] Name or service not known

During handling of the above exception, another exception occurred:

Traceback (most recent call last):
  File "/home/airflow/.local/lib/python3.8/site-packages/urllib3/connectionpool.py", line 715, in urlopen
    httplib_response = self._make_request(
  File "/home/airflow/.local/lib/python3.8/site-packages/urllib3/connectionpool.py", line 404, in _make_request
    self._validate_conn(conn)
  File "/home/airflow/.local/lib/python3.8/site-packages/urllib3/connectionpool.py", line 1058, in _validate_conn
    conn.connect()
  File "/home/airflow/.local/lib/python3.8/site-packages/urllib3/connection.py", line 363, in connect
    self.sock = conn = self._new_conn()
  File "/home/airflow/.local/lib/python3.8/site-packages/urllib3/connection.py", line 186, in _new_conn
    raise NewConnectionError(
urllib3.exceptions.NewConnectionError: <urllib3.connection.HTTPSConnection object at 0x7f29130a40d0>: Failed to establish a new connection: [Errno -2] Name or service not known

During handling of the above exception, another exception occurred:

Traceback (most recent call last):
  File "/home/airflow/.local/lib/python3.8/site-packages/requests/adapters.py", line 486, in send
    resp = conn.urlopen(
  File "/home/airflow/.local/lib/python3.8/site-packages/urllib3/connectionpool.py", line 799, in urlopen
    retries = retries.increment(
  File "/home/airflow/.local/lib/python3.8/site-packages/urllib3/util/retry.py", line 592, in increment
    raise MaxRetryError(_pool, url, error or ResponseError(cause))
urllib3.exceptions.MaxRetryError: HTTPSConnectionPool(host='api.binance.com', port=443): Max retries exceeded with url: /api/v3/account?timestamp=1722121457993&signature=2d4b377d8c9a9a692225cc1fb4474c041af36d28aa794da227d22d43281b56a2 (Caused by NewConnectionError('<urllib3.connection.HTTPSConnection object at 0x7f29130a40d0>: Failed to establish a new connection: [Errno -2] Name or service not known'))

During handling of the above exception, another exception occurred:

Traceback (most recent call last):
  File "/home/airflow/.local/lib/python3.8/site-packages/airflow/models/taskinstance.py", line 433, in _execute_task
    result = execute_callable(context=context, **execute_callable_kwargs)
  File "/home/airflow/.local/lib/python3.8/site-packages/airflow/operators/python.py", line 199, in execute
    return_value = self.execute_callable()
  File "/home/airflow/.local/lib/python3.8/site-packages/airflow/operators/python.py", line 216, in execute_callable
    return self.python_callable(*self.op_args, **self.op_kwargs)
  File "/opt/airflow/dags/crypto_pipeline_dag.py", line 28, in fetch_data_with_xcom
    df = fetch_data()
  File "/opt/airflow/Program.py", line 11, in fetch_data
    return generate_dataframe(api_key, signature_key)
  File "/opt/airflow/src/generate_data_frame.py", line 17, in generate_dataframe
    crypto_amounts = get_crypto_amounts(api_key, signature_key)
  File "/opt/airflow/src/extract_crypto_amounts.py", line 20, in get_crypto_amounts
    response = requests.get(url, headers=headers)
  File "/home/airflow/.local/lib/python3.8/site-packages/requests/api.py", line 73, in get
    return request("get", url, params=params, **kwargs)
  File "/home/airflow/.local/lib/python3.8/site-packages/requests/api.py", line 59, in request
    return session.request(method=method, url=url, **kwargs)
  File "/home/airflow/.local/lib/python3.8/site-packages/requests/sessions.py", line 589, in request
    resp = self.send(prep, **send_kwargs)
  File "/home/airflow/.local/lib/python3.8/site-packages/requests/sessions.py", line 703, in send
    r = adapter.send(request, **kwargs)
  File "/home/airflow/.local/lib/python3.8/site-packages/requests/adapters.py", line 519, in send
    raise ConnectionError(e, request=request)
requests.exceptions.ConnectionError: HTTPSConnectionPool(host='api.binance.com', port=443): Max retries exceeded with url: /api/v3/account?timestamp=1722121457993&signature=2d4b377d8c9a9a692225cc1fb4474c041af36d28aa794da227d22d43281b56a2 (Caused by NewConnectionError('<urllib3.connection.HTTPSConnection object at 0x7f29130a40d0>: Failed to establish a new connection: [Errno -2] Name or service not known'))
[2024-07-27T23:06:02.797+0000] {taskinstance.py:1138} INFO - Marking task as FAILED. dag_id=crypto_pipeline, task_id=fetch_data, execution_date=20240727T224500, start_date=20240727T230417, end_date=20240727T230602
[2024-07-27T23:06:02.825+0000] {standard_task_runner.py:107} ERROR - Failed to execute job 1440 for task fetch_data (HTTPSConnectionPool(host='api.binance.com', port=443): Max retries exceeded with url: /api/v3/account?timestamp=1722121457993&signature=2d4b377d8c9a9a692225cc1fb4474c041af36d28aa794da227d22d43281b56a2 (Caused by NewConnectionError('<urllib3.connection.HTTPSConnection object at 0x7f29130a40d0>: Failed to establish a new connection: [Errno -2] Name or service not known')); 29002)
[2024-07-27T23:06:02.868+0000] {local_task_job_runner.py:234} INFO - Task exited with return code 1
[2024-07-27T23:06:02.893+0000] {taskinstance.py:3280} INFO - 0 downstream tasks scheduled from follow-on schedule check
