[2024-07-19T18:30:09.389+0000] {taskinstance.py:1956} INFO - Dependencies all met for dep_context=non-requeueable deps ti=<TaskInstance: crypto_pipeline.load_data scheduled__2024-07-19T18:25:00+00:00 [queued]>
[2024-07-19T18:30:09.399+0000] {taskinstance.py:1956} INFO - Dependencies all met for dep_context=requeueable deps ti=<TaskInstance: crypto_pipeline.load_data scheduled__2024-07-19T18:25:00+00:00 [queued]>
[2024-07-19T18:30:09.400+0000] {taskinstance.py:2170} INFO - Starting attempt 1 of 1
[2024-07-19T18:30:09.414+0000] {taskinstance.py:2191} INFO - Executing <Task(PythonOperator): load_data> on 2024-07-19 18:25:00+00:00
[2024-07-19T18:30:09.422+0000] {standard_task_runner.py:60} INFO - Started process 630 to run task
[2024-07-19T18:30:09.427+0000] {standard_task_runner.py:87} INFO - Running: ['***', 'tasks', 'run', 'crypto_pipeline', 'load_data', 'scheduled__2024-07-19T18:25:00+00:00', '--job-id', '322', '--raw', '--subdir', 'DAGS_FOLDER/crypto_pipeline_dag.py', '--cfg-path', '/tmp/tmp9zpq7zry']
[2024-07-19T18:30:09.428+0000] {standard_task_runner.py:88} INFO - Job 322: Subtask load_data
[2024-07-19T18:30:09.649+0000] {task_command.py:423} INFO - Running <TaskInstance: crypto_pipeline.load_data scheduled__2024-07-19T18:25:00+00:00 [running]> on host 58dd90220664
[2024-07-19T18:30:09.731+0000] {taskinstance.py:2480} INFO - Exporting env vars: AIRFLOW_CTX_DAG_OWNER='***' AIRFLOW_CTX_DAG_ID='crypto_pipeline' AIRFLOW_CTX_TASK_ID='load_data' AIRFLOW_CTX_EXECUTION_DATE='2024-07-19T18:25:00+00:00' AIRFLOW_CTX_TRY_NUMBER='1' AIRFLOW_CTX_DAG_RUN_ID='scheduled__2024-07-19T18:25:00+00:00'
[2024-07-19T18:30:09.748+0000] {taskinstance.py:2698} ERROR - Task failed with exception
Traceback (most recent call last):
  File "/home/airflow/.local/lib/python3.8/site-packages/airflow/models/taskinstance.py", line 433, in _execute_task
    result = execute_callable(context=context, **execute_callable_kwargs)
  File "/home/airflow/.local/lib/python3.8/site-packages/airflow/operators/python.py", line 199, in execute
    return_value = self.execute_callable()
  File "/home/airflow/.local/lib/python3.8/site-packages/airflow/operators/python.py", line 216, in execute_callable
    return self.python_callable(*self.op_args, **self.op_kwargs)
  File "/opt/airflow/dags/crypto_pipeline_dag.py", line 66, in load_data_with_xcom
    load_data(data)
  File "/opt/airflow/Program.py", line 103, in load_data
    fetch_and_load(host, port, database, user, password, **data)
TypeError: fetch_and_load() got an unexpected keyword argument 'datetime_col'
[2024-07-19T18:30:09.761+0000] {taskinstance.py:1138} INFO - Marking task as FAILED. dag_id=crypto_pipeline, task_id=load_data, execution_date=20240719T182500, start_date=20240719T183009, end_date=20240719T183009
[2024-07-19T18:30:09.773+0000] {standard_task_runner.py:107} ERROR - Failed to execute job 322 for task load_data (fetch_and_load() got an unexpected keyword argument 'datetime_col'; 630)
[2024-07-19T18:30:09.800+0000] {local_task_job_runner.py:234} INFO - Task exited with return code 1
[2024-07-19T18:30:09.823+0000] {taskinstance.py:3280} INFO - 0 downstream tasks scheduled from follow-on schedule check
