[2024-07-18T19:59:29.031+0000] {taskinstance.py:1956} INFO - Dependencies all met for dep_context=non-requeueable deps ti=<TaskInstance: crypto_pipeline.fetch_and_load scheduled__2023-07-26T12:00:00+00:00 [queued]>
[2024-07-18T19:59:29.043+0000] {taskinstance.py:1956} INFO - Dependencies all met for dep_context=requeueable deps ti=<TaskInstance: crypto_pipeline.fetch_and_load scheduled__2023-07-26T12:00:00+00:00 [queued]>
[2024-07-18T19:59:29.045+0000] {taskinstance.py:2170} INFO - Starting attempt 1 of 1
[2024-07-18T19:59:29.060+0000] {taskinstance.py:2191} INFO - Executing <Task(PythonOperator): fetch_and_load> on 2023-07-26 12:00:00+00:00
[2024-07-18T19:59:29.069+0000] {standard_task_runner.py:60} INFO - Started process 380 to run task
[2024-07-18T19:59:29.073+0000] {standard_task_runner.py:87} INFO - Running: ['***', 'tasks', 'run', 'crypto_pipeline', 'fetch_and_load', 'scheduled__2023-07-26T12:00:00+00:00', '--job-id', '61', '--raw', '--subdir', 'DAGS_FOLDER/crypto_pipeline.py', '--cfg-path', '/tmp/tmp2z7u_gq5']
[2024-07-18T19:59:29.075+0000] {standard_task_runner.py:88} INFO - Job 61: Subtask fetch_and_load
[2024-07-18T19:59:29.128+0000] {task_command.py:423} INFO - Running <TaskInstance: crypto_pipeline.fetch_and_load scheduled__2023-07-26T12:00:00+00:00 [running]> on host 83ce34bce632
[2024-07-18T19:59:29.215+0000] {taskinstance.py:2480} INFO - Exporting env vars: AIRFLOW_CTX_DAG_EMAIL='lorenzo.silva@poatek.com' AIRFLOW_CTX_DAG_OWNER='***' AIRFLOW_CTX_DAG_ID='crypto_pipeline' AIRFLOW_CTX_TASK_ID='fetch_and_load' AIRFLOW_CTX_EXECUTION_DATE='2023-07-26T12:00:00+00:00' AIRFLOW_CTX_TRY_NUMBER='1' AIRFLOW_CTX_DAG_RUN_ID='scheduled__2023-07-26T12:00:00+00:00'
[2024-07-18T19:59:29.217+0000] {taskinstance.py:2698} ERROR - Task failed with exception
Traceback (most recent call last):
  File "/home/airflow/.local/lib/python3.8/site-packages/airflow/models/taskinstance.py", line 433, in _execute_task
    result = execute_callable(context=context, **execute_callable_kwargs)
  File "/home/airflow/.local/lib/python3.8/site-packages/airflow/operators/python.py", line 199, in execute
    return_value = self.execute_callable()
  File "/home/airflow/.local/lib/python3.8/site-packages/airflow/operators/python.py", line 216, in execute_callable
    return self.python_callable(*self.op_args, **self.op_kwargs)
TypeError: fetch_and_load() missing 20 required positional arguments: 'host', 'port', 'database', 'user', 'password', 'datetime', 'btcusdt_rate', 'ethusdt_rate', 'solusdt_rate', 'btcbrl_rate', 'ethbrl_rate', 'solbrl_rate', 'btcusdt_total', 'ethusdt_total', 'solusdt_total', 'btcbrl_total', 'ethbrl_total', 'solbrl_total', 'brl_total', and 'usdt_total'
[2024-07-18T19:59:29.225+0000] {taskinstance.py:1138} INFO - Marking task as FAILED. dag_id=crypto_pipeline, task_id=fetch_and_load, execution_date=20230726T120000, start_date=20240718T195929, end_date=20240718T195929
[2024-07-18T19:59:29.245+0000] {warnings.py:109} WARNING - /home/***/.local/lib/python3.8/site-packages/***/utils/email.py:154: RemovedInAirflow3Warning: Fetching SMTP credentials from configuration variables will be deprecated in a future release. Please set credentials using a connection instead.
  send_mime_email(e_from=mail_from, e_to=recipients, mime_msg=msg, conn_id=conn_id, dryrun=dryrun)

[2024-07-18T19:59:29.246+0000] {configuration.py:1046} WARNING - section/key [smtp/smtp_user] not found in config
[2024-07-18T19:59:29.247+0000] {email.py:270} INFO - Email alerting: attempt 1
[2024-07-18T19:59:29.256+0000] {configuration.py:1046} WARNING - section/key [smtp/smtp_user] not found in config
[2024-07-18T19:59:29.257+0000] {email.py:270} INFO - Email alerting: attempt 1
[2024-07-18T19:59:29.259+0000] {taskinstance.py:826} ERROR - Failed to send email to: lorenzo.silva@poatek.com
Traceback (most recent call last):
  File "/home/airflow/.local/lib/python3.8/site-packages/airflow/models/taskinstance.py", line 2334, in _run_raw_task
    self._execute_task_with_callbacks(context, test_mode, session=session)
  File "/home/airflow/.local/lib/python3.8/site-packages/airflow/models/taskinstance.py", line 2499, in _execute_task_with_callbacks
    result = self._execute_task(context, task_orig)
  File "/home/airflow/.local/lib/python3.8/site-packages/airflow/models/taskinstance.py", line 2516, in _execute_task
    return _execute_task(self, context, task_orig)
  File "/home/airflow/.local/lib/python3.8/site-packages/airflow/models/taskinstance.py", line 433, in _execute_task
    result = execute_callable(context=context, **execute_callable_kwargs)
  File "/home/airflow/.local/lib/python3.8/site-packages/airflow/operators/python.py", line 199, in execute
    return_value = self.execute_callable()
  File "/home/airflow/.local/lib/python3.8/site-packages/airflow/operators/python.py", line 216, in execute_callable
    return self.python_callable(*self.op_args, **self.op_kwargs)
TypeError: fetch_and_load() missing 20 required positional arguments: 'host', 'port', 'database', 'user', 'password', 'datetime', 'btcusdt_rate', 'ethusdt_rate', 'solusdt_rate', 'btcbrl_rate', 'ethbrl_rate', 'solbrl_rate', 'btcusdt_total', 'ethusdt_total', 'solusdt_total', 'btcbrl_total', 'ethbrl_total', 'solbrl_total', 'brl_total', and 'usdt_total'

During handling of the above exception, another exception occurred:

Traceback (most recent call last):
  File "/home/airflow/.local/lib/python3.8/site-packages/airflow/models/taskinstance.py", line 1000, in _email_alert
    send_email(task.email, subject, html_content)
  File "/home/airflow/.local/lib/python3.8/site-packages/airflow/utils/email.py", line 80, in send_email
    return backend(
  File "/home/airflow/.local/lib/python3.8/site-packages/airflow/utils/email.py", line 154, in send_email_smtp
    send_mime_email(e_from=mail_from, e_to=recipients, mime_msg=msg, conn_id=conn_id, dryrun=dryrun)
  File "/home/airflow/.local/lib/python3.8/site-packages/airflow/utils/email.py", line 272, in send_mime_email
    smtp_conn = _get_smtp_connection(smtp_host, smtp_port, smtp_timeout, smtp_ssl)
  File "/home/airflow/.local/lib/python3.8/site-packages/airflow/utils/email.py", line 316, in _get_smtp_connection
    return smtplib.SMTP(host=host, port=port, timeout=timeout)
  File "/usr/local/lib/python3.8/smtplib.py", line 255, in __init__
    (code, msg) = self.connect(host, port)
  File "/usr/local/lib/python3.8/smtplib.py", line 339, in connect
    self.sock = self._get_socket(host, port, self.timeout)
  File "/usr/local/lib/python3.8/smtplib.py", line 310, in _get_socket
    return socket.create_connection((host, port), timeout,
  File "/usr/local/lib/python3.8/socket.py", line 808, in create_connection
    raise err
  File "/usr/local/lib/python3.8/socket.py", line 796, in create_connection
    sock.connect(sa)
ConnectionRefusedError: [Errno 111] Connection refused

During handling of the above exception, another exception occurred:

Traceback (most recent call last):
  File "/home/airflow/.local/lib/python3.8/site-packages/airflow/models/taskinstance.py", line 824, in _handle_failure
    task_instance.email_alert(error, failure_context["task"])
  File "/home/airflow/.local/lib/python3.8/site-packages/airflow/models/taskinstance.py", line 2946, in email_alert
    _email_alert(task_instance=self, exception=exception, task=task)
  File "/home/airflow/.local/lib/python3.8/site-packages/airflow/models/taskinstance.py", line 1002, in _email_alert
    send_email(task.email, subject, html_content_err)
  File "/home/airflow/.local/lib/python3.8/site-packages/airflow/utils/email.py", line 80, in send_email
    return backend(
  File "/home/airflow/.local/lib/python3.8/site-packages/airflow/utils/email.py", line 154, in send_email_smtp
    send_mime_email(e_from=mail_from, e_to=recipients, mime_msg=msg, conn_id=conn_id, dryrun=dryrun)
  File "/home/airflow/.local/lib/python3.8/site-packages/airflow/utils/email.py", line 272, in send_mime_email
    smtp_conn = _get_smtp_connection(smtp_host, smtp_port, smtp_timeout, smtp_ssl)
  File "/home/airflow/.local/lib/python3.8/site-packages/airflow/utils/email.py", line 316, in _get_smtp_connection
    return smtplib.SMTP(host=host, port=port, timeout=timeout)
  File "/usr/local/lib/python3.8/smtplib.py", line 255, in __init__
    (code, msg) = self.connect(host, port)
  File "/usr/local/lib/python3.8/smtplib.py", line 339, in connect
    self.sock = self._get_socket(host, port, self.timeout)
  File "/usr/local/lib/python3.8/smtplib.py", line 310, in _get_socket
    return socket.create_connection((host, port), timeout,
  File "/usr/local/lib/python3.8/socket.py", line 808, in create_connection
    raise err
  File "/usr/local/lib/python3.8/socket.py", line 796, in create_connection
    sock.connect(sa)
ConnectionRefusedError: [Errno 111] Connection refused
[2024-07-18T19:59:29.276+0000] {standard_task_runner.py:107} ERROR - Failed to execute job 61 for task fetch_and_load (fetch_and_load() missing 20 required positional arguments: 'host', 'port', 'database', 'user', 'password', 'datetime', 'btcusdt_rate', 'ethusdt_rate', 'solusdt_rate', 'btcbrl_rate', 'ethbrl_rate', 'solbrl_rate', 'btcusdt_total', 'ethusdt_total', 'solusdt_total', 'btcbrl_total', 'ethbrl_total', 'solbrl_total', 'brl_total', and 'usdt_total'; 380)
[2024-07-18T19:59:29.326+0000] {local_task_job_runner.py:234} INFO - Task exited with return code 1
[2024-07-18T19:59:29.344+0000] {taskinstance.py:3280} INFO - 0 downstream tasks scheduled from follow-on schedule check
